17.12.2023 01:07:28 [ERROR] Internal Server Error: /news/add
C:\Users\user\projects\Skillfactory\Project News Portal\venv\Lib\site-packages\django\utils\log.py
(<class 'kombu.exceptions.OperationalError'>, OperationalError('Error 10061 connecting to 127.0.0.1:6379. Подключение не установлено, т.к. конечный компьютер отверг запрос на подключение.'), <traceback object at 0x000001F13A097180>)
Traceback (most recent call last):
  File "C:\Users\user\projects\Skillfactory\Project News Portal\venv\Lib\site-packages\redis\connection.py", line 707, in connect
    sock = self.retry.call_with_retry(
           ^^^^^^^^^^^^^^^^^^^^^^^^^^^
  File "C:\Users\user\projects\Skillfactory\Project News Portal\venv\Lib\site-packages\redis\retry.py", line 46, in call_with_retry
    return do()
           ^^^^
  File "C:\Users\user\projects\Skillfactory\Project News Portal\venv\Lib\site-packages\redis\connection.py", line 708, in <lambda>
    lambda: self._connect(), lambda error: self.disconnect(error)
            ^^^^^^^^^^^^^^^
  File "C:\Users\user\projects\Skillfactory\Project News Portal\venv\Lib\site-packages\redis\connection.py", line 1006, in _connect
    raise err
  File "C:\Users\user\projects\Skillfactory\Project News Portal\venv\Lib\site-packages\redis\connection.py", line 994, in _connect
    sock.connect(socket_address)
ConnectionRefusedError: [WinError 10061] Подключение не установлено, т.к. конечный компьютер отверг запрос на подключение

During handling of the above exception, another exception occurred:

Traceback (most recent call last):
  File "C:\Users\user\projects\Skillfactory\Project News Portal\venv\Lib\site-packages\celery\backends\redis.py", line 127, in reconnect_on_error
    yield
  File "C:\Users\user\projects\Skillfactory\Project News Portal\venv\Lib\site-packages\celery\backends\redis.py", line 177, in _consume_from
    self._pubsub.subscribe(key)
  File "C:\Users\user\projects\Skillfactory\Project News Portal\venv\Lib\site-packages\redis\client.py", line 1634, in subscribe
    ret_val = self.execute_command("SUBSCRIBE", *new_channels.keys())
              ^^^^^^^^^^^^^^^^^^^^^^^^^^^^^^^^^^^^^^^^^^^^^^^^^^^^^^^
  File "C:\Users\user\projects\Skillfactory\Project News Portal\venv\Lib\site-packages\redis\client.py", line 1469, in execute_command
    self.connection = self.connection_pool.get_connection(
                      ^^^^^^^^^^^^^^^^^^^^^^^^^^^^^^^^^^^^
  File "C:\Users\user\projects\Skillfactory\Project News Portal\venv\Lib\site-packages\redis\connection.py", line 1461, in get_connection
    connection.connect()
  File "C:\Users\user\projects\Skillfactory\Project News Portal\venv\Lib\site-packages\redis\connection.py", line 713, in connect
    raise ConnectionError(self._error_message(e))
redis.exceptions.ConnectionError: Error 10061 connecting to 127.0.0.1:6379. Подключение не установлено, т.к. конечный компьютер отверг запрос на подключение.

During handling of the above exception, another exception occurred:

Traceback (most recent call last):
  File "C:\Users\user\projects\Skillfactory\Project News Portal\venv\Lib\site-packages\redis\connection.py", line 707, in connect
    sock = self.retry.call_with_retry(
           ^^^^^^^^^^^^^^^^^^^^^^^^^^^
  File "C:\Users\user\projects\Skillfactory\Project News Portal\venv\Lib\site-packages\redis\retry.py", line 46, in call_with_retry
    return do()
           ^^^^
  File "C:\Users\user\projects\Skillfactory\Project News Portal\venv\Lib\site-packages\redis\connection.py", line 708, in <lambda>
    lambda: self._connect(), lambda error: self.disconnect(error)
            ^^^^^^^^^^^^^^^
  File "C:\Users\user\projects\Skillfactory\Project News Portal\venv\Lib\site-packages\redis\connection.py", line 1006, in _connect
    raise err
  File "C:\Users\user\projects\Skillfactory\Project News Portal\venv\Lib\site-packages\redis\connection.py", line 994, in _connect
    sock.connect(socket_address)
ConnectionRefusedError: [WinError 10061] Подключение не установлено, т.к. конечный компьютер отверг запрос на подключение

During handling of the above exception, another exception occurred:

Traceback (most recent call last):
  File "C:\Users\user\projects\Skillfactory\Project News Portal\venv\Lib\site-packages\kombu\connection.py", line 472, in _reraise_as_library_errors
    yield
  File "C:\Users\user\projects\Skillfactory\Project News Portal\venv\Lib\site-packages\celery\app\base.py", line 797, in send_task
    self.backend.on_task_call(P, task_id)
  File "C:\Users\user\projects\Skillfactory\Project News Portal\venv\Lib\site-packages\celery\backends\redis.py", line 373, in on_task_call
    self.result_consumer.consume_from(task_id)
  File "C:\Users\user\projects\Skillfactory\Project News Portal\venv\Lib\site-packages\celery\backends\redis.py", line 169, in consume_from
    return self.start(task_id)
           ^^^^^^^^^^^^^^^^^^^
  File "C:\Users\user\projects\Skillfactory\Project News Portal\venv\Lib\site-packages\celery\backends\redis.py", line 147, in start
    self._consume_from(initial_task_id)
  File "C:\Users\user\projects\Skillfactory\Project News Portal\venv\Lib\site-packages\celery\backends\redis.py", line 176, in _consume_from
    with self.reconnect_on_error():
  File "C:\Users\user\AppData\Local\Programs\Python\Python311\Lib\contextlib.py", line 155, in __exit__
    self.gen.throw(typ, value, traceback)
  File "C:\Users\user\projects\Skillfactory\Project News Portal\venv\Lib\site-packages\celery\backends\redis.py", line 130, in reconnect_on_error
    self._ensure(self._reconnect_pubsub, ())
  File "C:\Users\user\projects\Skillfactory\Project News Portal\venv\Lib\site-packages\celery\backends\redis.py", line 384, in ensure
    return retry_over_time(
           ^^^^^^^^^^^^^^^^
  File "C:\Users\user\projects\Skillfactory\Project News Portal\venv\Lib\site-packages\kombu\utils\functional.py", line 318, in retry_over_time
    return fun(*args, **kwargs)
           ^^^^^^^^^^^^^^^^^^^^
  File "C:\Users\user\projects\Skillfactory\Project News Portal\venv\Lib\site-packages\celery\backends\redis.py", line 106, in _reconnect_pubsub
    metas = self.backend.client.mget(self.subscribed_to)
            ^^^^^^^^^^^^^^^^^^^^^^^^^^^^^^^^^^^^^^^^^^^^
  File "C:\Users\user\projects\Skillfactory\Project News Portal\venv\Lib\site-packages\redis\commands\core.py", line 2002, in mget
    return self.execute_command("MGET", *args, **options)
           ^^^^^^^^^^^^^^^^^^^^^^^^^^^^^^^^^^^^^^^^^^^^^^
  File "C:\Users\user\projects\Skillfactory\Project News Portal\venv\Lib\site-packages\redis\client.py", line 1266, in execute_command
    conn = self.connection or pool.get_connection(command_name, **options)
                              ^^^^^^^^^^^^^^^^^^^^^^^^^^^^^^^^^^^^^^^^^^^^
  File "C:\Users\user\projects\Skillfactory\Project News Portal\venv\Lib\site-packages\redis\connection.py", line 1461, in get_connection
    connection.connect()
  File "C:\Users\user\projects\Skillfactory\Project News Portal\venv\Lib\site-packages\redis\connection.py", line 713, in connect
    raise ConnectionError(self._error_message(e))
redis.exceptions.ConnectionError: Error 10061 connecting to 127.0.0.1:6379. Подключение не установлено, т.к. конечный компьютер отверг запрос на подключение.

The above exception was the direct cause of the following exception:

Traceback (most recent call last):
  File "C:\Users\user\projects\Skillfactory\Project News Portal\venv\Lib\site-packages\django\core\handlers\exception.py", line 55, in inner
    response = get_response(request)
               ^^^^^^^^^^^^^^^^^^^^^
  File "C:\Users\user\projects\Skillfactory\Project News Portal\venv\Lib\site-packages\django\core\handlers\base.py", line 197, in _get_response
    response = wrapped_callback(request, *callback_args, **callback_kwargs)
               ^^^^^^^^^^^^^^^^^^^^^^^^^^^^^^^^^^^^^^^^^^^^^^^^^^^^^^^^^^^^
  File "C:\Users\user\projects\Skillfactory\Project News Portal\venv\Lib\site-packages\django\views\generic\base.py", line 104, in view
    return self.dispatch(request, *args, **kwargs)
           ^^^^^^^^^^^^^^^^^^^^^^^^^^^^^^^^^^^^^^^
  File "C:\Users\user\projects\Skillfactory\Project News Portal\venv\Lib\site-packages\django\contrib\auth\mixins.py", line 73, in dispatch
    return super().dispatch(request, *args, **kwargs)
           ^^^^^^^^^^^^^^^^^^^^^^^^^^^^^^^^^^^^^^^^^^
  File "C:\Users\user\projects\Skillfactory\Project News Portal\venv\Lib\site-packages\django\contrib\auth\mixins.py", line 109, in dispatch
    return super().dispatch(request, *args, **kwargs)
           ^^^^^^^^^^^^^^^^^^^^^^^^^^^^^^^^^^^^^^^^^^
  File "C:\Users\user\projects\Skillfactory\Project News Portal\venv\Lib\site-packages\django\views\generic\base.py", line 143, in dispatch
    return handler(request, *args, **kwargs)
           ^^^^^^^^^^^^^^^^^^^^^^^^^^^^^^^^^
  File "C:\Users\user\projects\Skillfactory\Project News Portal\News_Portal\news\views.py", line 60, in post
    notify_subscribers.delay(new_post.pk)   # вызов задачи на отправку письма подписчикам, при создании поста
    ^^^^^^^^^^^^^^^^^^^^^^^^^^^^^^^^^^^^^
  File "C:\Users\user\projects\Skillfactory\Project News Portal\venv\Lib\site-packages\celery\app\task.py", line 444, in delay
    return self.apply_async(args, kwargs)
           ^^^^^^^^^^^^^^^^^^^^^^^^^^^^^^
  File "C:\Users\user\projects\Skillfactory\Project News Portal\venv\Lib\site-packages\celery\app\task.py", line 594, in apply_async
    return app.send_task(
           ^^^^^^^^^^^^^^
  File "C:\Users\user\projects\Skillfactory\Project News Portal\venv\Lib\site-packages\celery\app\base.py", line 795, in send_task
    with P.connection._reraise_as_library_errors():
  File "C:\Users\user\AppData\Local\Programs\Python\Python311\Lib\contextlib.py", line 155, in __exit__
    self.gen.throw(typ, value, traceback)
  File "C:\Users\user\projects\Skillfactory\Project News Portal\venv\Lib\site-packages\kombu\connection.py", line 476, in _reraise_as_library_errors
    raise ConnectionError(str(exc)) from exc
kombu.exceptions.OperationalError: Error 10061 connecting to 127.0.0.1:6379. Подключение не установлено, т.к. конечный компьютер отверг запрос на подключение.
17.12.2023 01:09:42 [ERROR] Internal Server Error: /news/add
C:\Users\user\projects\Skillfactory\Project News Portal\venv\Lib\site-packages\django\utils\log.py
(<class 'kombu.exceptions.OperationalError'>, OperationalError('Error 10061 connecting to 127.0.0.1:6379. Подключение не установлено, т.к. конечный компьютер отверг запрос на подключение.'), <traceback object at 0x000001F13A26FA80>)
Traceback (most recent call last):
  File "C:\Users\user\projects\Skillfactory\Project News Portal\venv\Lib\site-packages\redis\connection.py", line 707, in connect
    sock = self.retry.call_with_retry(
           ^^^^^^^^^^^^^^^^^^^^^^^^^^^
  File "C:\Users\user\projects\Skillfactory\Project News Portal\venv\Lib\site-packages\redis\retry.py", line 46, in call_with_retry
    return do()
           ^^^^
  File "C:\Users\user\projects\Skillfactory\Project News Portal\venv\Lib\site-packages\redis\connection.py", line 708, in <lambda>
    lambda: self._connect(), lambda error: self.disconnect(error)
            ^^^^^^^^^^^^^^^
  File "C:\Users\user\projects\Skillfactory\Project News Portal\venv\Lib\site-packages\redis\connection.py", line 1006, in _connect
    raise err
  File "C:\Users\user\projects\Skillfactory\Project News Portal\venv\Lib\site-packages\redis\connection.py", line 994, in _connect
    sock.connect(socket_address)
ConnectionRefusedError: [WinError 10061] Подключение не установлено, т.к. конечный компьютер отверг запрос на подключение

During handling of the above exception, another exception occurred:

Traceback (most recent call last):
  File "C:\Users\user\projects\Skillfactory\Project News Portal\venv\Lib\site-packages\celery\backends\redis.py", line 127, in reconnect_on_error
    yield
  File "C:\Users\user\projects\Skillfactory\Project News Portal\venv\Lib\site-packages\celery\backends\redis.py", line 177, in _consume_from
    self._pubsub.subscribe(key)
  File "C:\Users\user\projects\Skillfactory\Project News Portal\venv\Lib\site-packages\redis\client.py", line 1634, in subscribe
    ret_val = self.execute_command("SUBSCRIBE", *new_channels.keys())
              ^^^^^^^^^^^^^^^^^^^^^^^^^^^^^^^^^^^^^^^^^^^^^^^^^^^^^^^
  File "C:\Users\user\projects\Skillfactory\Project News Portal\venv\Lib\site-packages\redis\client.py", line 1469, in execute_command
    self.connection = self.connection_pool.get_connection(
                      ^^^^^^^^^^^^^^^^^^^^^^^^^^^^^^^^^^^^
  File "C:\Users\user\projects\Skillfactory\Project News Portal\venv\Lib\site-packages\redis\connection.py", line 1461, in get_connection
    connection.connect()
  File "C:\Users\user\projects\Skillfactory\Project News Portal\venv\Lib\site-packages\redis\connection.py", line 713, in connect
    raise ConnectionError(self._error_message(e))
redis.exceptions.ConnectionError: Error 10061 connecting to 127.0.0.1:6379. Подключение не установлено, т.к. конечный компьютер отверг запрос на подключение.

During handling of the above exception, another exception occurred:

Traceback (most recent call last):
  File "C:\Users\user\projects\Skillfactory\Project News Portal\venv\Lib\site-packages\redis\connection.py", line 707, in connect
    sock = self.retry.call_with_retry(
           ^^^^^^^^^^^^^^^^^^^^^^^^^^^
  File "C:\Users\user\projects\Skillfactory\Project News Portal\venv\Lib\site-packages\redis\retry.py", line 46, in call_with_retry
    return do()
           ^^^^
  File "C:\Users\user\projects\Skillfactory\Project News Portal\venv\Lib\site-packages\redis\connection.py", line 708, in <lambda>
    lambda: self._connect(), lambda error: self.disconnect(error)
            ^^^^^^^^^^^^^^^
  File "C:\Users\user\projects\Skillfactory\Project News Portal\venv\Lib\site-packages\redis\connection.py", line 1006, in _connect
    raise err
  File "C:\Users\user\projects\Skillfactory\Project News Portal\venv\Lib\site-packages\redis\connection.py", line 994, in _connect
    sock.connect(socket_address)
ConnectionRefusedError: [WinError 10061] Подключение не установлено, т.к. конечный компьютер отверг запрос на подключение

During handling of the above exception, another exception occurred:

Traceback (most recent call last):
  File "C:\Users\user\projects\Skillfactory\Project News Portal\venv\Lib\site-packages\kombu\connection.py", line 472, in _reraise_as_library_errors
    yield
  File "C:\Users\user\projects\Skillfactory\Project News Portal\venv\Lib\site-packages\celery\app\base.py", line 797, in send_task
    self.backend.on_task_call(P, task_id)
  File "C:\Users\user\projects\Skillfactory\Project News Portal\venv\Lib\site-packages\celery\backends\redis.py", line 373, in on_task_call
    self.result_consumer.consume_from(task_id)
  File "C:\Users\user\projects\Skillfactory\Project News Portal\venv\Lib\site-packages\celery\backends\redis.py", line 169, in consume_from
    return self.start(task_id)
           ^^^^^^^^^^^^^^^^^^^
  File "C:\Users\user\projects\Skillfactory\Project News Portal\venv\Lib\site-packages\celery\backends\redis.py", line 147, in start
    self._consume_from(initial_task_id)
  File "C:\Users\user\projects\Skillfactory\Project News Portal\venv\Lib\site-packages\celery\backends\redis.py", line 176, in _consume_from
    with self.reconnect_on_error():
  File "C:\Users\user\AppData\Local\Programs\Python\Python311\Lib\contextlib.py", line 155, in __exit__
    self.gen.throw(typ, value, traceback)
  File "C:\Users\user\projects\Skillfactory\Project News Portal\venv\Lib\site-packages\celery\backends\redis.py", line 130, in reconnect_on_error
    self._ensure(self._reconnect_pubsub, ())
  File "C:\Users\user\projects\Skillfactory\Project News Portal\venv\Lib\site-packages\celery\backends\redis.py", line 384, in ensure
    return retry_over_time(
           ^^^^^^^^^^^^^^^^
  File "C:\Users\user\projects\Skillfactory\Project News Portal\venv\Lib\site-packages\kombu\utils\functional.py", line 318, in retry_over_time
    return fun(*args, **kwargs)
           ^^^^^^^^^^^^^^^^^^^^
  File "C:\Users\user\projects\Skillfactory\Project News Portal\venv\Lib\site-packages\celery\backends\redis.py", line 106, in _reconnect_pubsub
    metas = self.backend.client.mget(self.subscribed_to)
            ^^^^^^^^^^^^^^^^^^^^^^^^^^^^^^^^^^^^^^^^^^^^
  File "C:\Users\user\projects\Skillfactory\Project News Portal\venv\Lib\site-packages\redis\commands\core.py", line 2002, in mget
    return self.execute_command("MGET", *args, **options)
           ^^^^^^^^^^^^^^^^^^^^^^^^^^^^^^^^^^^^^^^^^^^^^^
  File "C:\Users\user\projects\Skillfactory\Project News Portal\venv\Lib\site-packages\redis\client.py", line 1266, in execute_command
    conn = self.connection or pool.get_connection(command_name, **options)
                              ^^^^^^^^^^^^^^^^^^^^^^^^^^^^^^^^^^^^^^^^^^^^
  File "C:\Users\user\projects\Skillfactory\Project News Portal\venv\Lib\site-packages\redis\connection.py", line 1461, in get_connection
    connection.connect()
  File "C:\Users\user\projects\Skillfactory\Project News Portal\venv\Lib\site-packages\redis\connection.py", line 713, in connect
    raise ConnectionError(self._error_message(e))
redis.exceptions.ConnectionError: Error 10061 connecting to 127.0.0.1:6379. Подключение не установлено, т.к. конечный компьютер отверг запрос на подключение.

The above exception was the direct cause of the following exception:

Traceback (most recent call last):
  File "C:\Users\user\projects\Skillfactory\Project News Portal\venv\Lib\site-packages\django\core\handlers\exception.py", line 55, in inner
    response = get_response(request)
               ^^^^^^^^^^^^^^^^^^^^^
  File "C:\Users\user\projects\Skillfactory\Project News Portal\venv\Lib\site-packages\django\core\handlers\base.py", line 197, in _get_response
    response = wrapped_callback(request, *callback_args, **callback_kwargs)
               ^^^^^^^^^^^^^^^^^^^^^^^^^^^^^^^^^^^^^^^^^^^^^^^^^^^^^^^^^^^^
  File "C:\Users\user\projects\Skillfactory\Project News Portal\venv\Lib\site-packages\django\views\generic\base.py", line 104, in view
    return self.dispatch(request, *args, **kwargs)
           ^^^^^^^^^^^^^^^^^^^^^^^^^^^^^^^^^^^^^^^
  File "C:\Users\user\projects\Skillfactory\Project News Portal\venv\Lib\site-packages\django\contrib\auth\mixins.py", line 73, in dispatch
    return super().dispatch(request, *args, **kwargs)
           ^^^^^^^^^^^^^^^^^^^^^^^^^^^^^^^^^^^^^^^^^^
  File "C:\Users\user\projects\Skillfactory\Project News Portal\venv\Lib\site-packages\django\contrib\auth\mixins.py", line 109, in dispatch
    return super().dispatch(request, *args, **kwargs)
           ^^^^^^^^^^^^^^^^^^^^^^^^^^^^^^^^^^^^^^^^^^
  File "C:\Users\user\projects\Skillfactory\Project News Portal\venv\Lib\site-packages\django\views\generic\base.py", line 143, in dispatch
    return handler(request, *args, **kwargs)
           ^^^^^^^^^^^^^^^^^^^^^^^^^^^^^^^^^
  File "C:\Users\user\projects\Skillfactory\Project News Portal\News_Portal\news\views.py", line 60, in post
    notify_subscribers.delay(new_post.pk)   # вызов задачи на отправку письма подписчикам, при создании поста
    ^^^^^^^^^^^^^^^^^^^^^^^^^^^^^^^^^^^^^
  File "C:\Users\user\projects\Skillfactory\Project News Portal\venv\Lib\site-packages\celery\app\task.py", line 444, in delay
    return self.apply_async(args, kwargs)
           ^^^^^^^^^^^^^^^^^^^^^^^^^^^^^^
  File "C:\Users\user\projects\Skillfactory\Project News Portal\venv\Lib\site-packages\celery\app\task.py", line 594, in apply_async
    return app.send_task(
           ^^^^^^^^^^^^^^
  File "C:\Users\user\projects\Skillfactory\Project News Portal\venv\Lib\site-packages\celery\app\base.py", line 795, in send_task
    with P.connection._reraise_as_library_errors():
  File "C:\Users\user\AppData\Local\Programs\Python\Python311\Lib\contextlib.py", line 155, in __exit__
    self.gen.throw(typ, value, traceback)
  File "C:\Users\user\projects\Skillfactory\Project News Portal\venv\Lib\site-packages\kombu\connection.py", line 476, in _reraise_as_library_errors
    raise ConnectionError(str(exc)) from exc
kombu.exceptions.OperationalError: Error 10061 connecting to 127.0.0.1:6379. Подключение не установлено, т.к. конечный компьютер отверг запрос на подключение.
17.12.2023 01:10:19 [ERROR] Internal Server Error: /news/add
C:\Users\user\projects\Skillfactory\Project News Portal\venv\Lib\site-packages\django\utils\log.py
(<class 'kombu.exceptions.OperationalError'>, OperationalError('Error 10061 connecting to 127.0.0.1:6379. Подключение не установлено, т.к. конечный компьютер отверг запрос на подключение.'), <traceback object at 0x000001F13A112940>)
Traceback (most recent call last):
  File "C:\Users\user\projects\Skillfactory\Project News Portal\venv\Lib\site-packages\redis\connection.py", line 707, in connect
    sock = self.retry.call_with_retry(
           ^^^^^^^^^^^^^^^^^^^^^^^^^^^
  File "C:\Users\user\projects\Skillfactory\Project News Portal\venv\Lib\site-packages\redis\retry.py", line 46, in call_with_retry
    return do()
           ^^^^
  File "C:\Users\user\projects\Skillfactory\Project News Portal\venv\Lib\site-packages\redis\connection.py", line 708, in <lambda>
    lambda: self._connect(), lambda error: self.disconnect(error)
            ^^^^^^^^^^^^^^^
  File "C:\Users\user\projects\Skillfactory\Project News Portal\venv\Lib\site-packages\redis\connection.py", line 1006, in _connect
    raise err
  File "C:\Users\user\projects\Skillfactory\Project News Portal\venv\Lib\site-packages\redis\connection.py", line 994, in _connect
    sock.connect(socket_address)
ConnectionRefusedError: [WinError 10061] Подключение не установлено, т.к. конечный компьютер отверг запрос на подключение

During handling of the above exception, another exception occurred:

Traceback (most recent call last):
  File "C:\Users\user\projects\Skillfactory\Project News Portal\venv\Lib\site-packages\celery\backends\redis.py", line 127, in reconnect_on_error
    yield
  File "C:\Users\user\projects\Skillfactory\Project News Portal\venv\Lib\site-packages\celery\backends\redis.py", line 177, in _consume_from
    self._pubsub.subscribe(key)
  File "C:\Users\user\projects\Skillfactory\Project News Portal\venv\Lib\site-packages\redis\client.py", line 1634, in subscribe
    ret_val = self.execute_command("SUBSCRIBE", *new_channels.keys())
              ^^^^^^^^^^^^^^^^^^^^^^^^^^^^^^^^^^^^^^^^^^^^^^^^^^^^^^^
  File "C:\Users\user\projects\Skillfactory\Project News Portal\venv\Lib\site-packages\redis\client.py", line 1469, in execute_command
    self.connection = self.connection_pool.get_connection(
                      ^^^^^^^^^^^^^^^^^^^^^^^^^^^^^^^^^^^^
  File "C:\Users\user\projects\Skillfactory\Project News Portal\venv\Lib\site-packages\redis\connection.py", line 1461, in get_connection
    connection.connect()
  File "C:\Users\user\projects\Skillfactory\Project News Portal\venv\Lib\site-packages\redis\connection.py", line 713, in connect
    raise ConnectionError(self._error_message(e))
redis.exceptions.ConnectionError: Error 10061 connecting to 127.0.0.1:6379. Подключение не установлено, т.к. конечный компьютер отверг запрос на подключение.

During handling of the above exception, another exception occurred:

Traceback (most recent call last):
  File "C:\Users\user\projects\Skillfactory\Project News Portal\venv\Lib\site-packages\redis\connection.py", line 707, in connect
    sock = self.retry.call_with_retry(
           ^^^^^^^^^^^^^^^^^^^^^^^^^^^
  File "C:\Users\user\projects\Skillfactory\Project News Portal\venv\Lib\site-packages\redis\retry.py", line 46, in call_with_retry
    return do()
           ^^^^
  File "C:\Users\user\projects\Skillfactory\Project News Portal\venv\Lib\site-packages\redis\connection.py", line 708, in <lambda>
    lambda: self._connect(), lambda error: self.disconnect(error)
            ^^^^^^^^^^^^^^^
  File "C:\Users\user\projects\Skillfactory\Project News Portal\venv\Lib\site-packages\redis\connection.py", line 1006, in _connect
    raise err
  File "C:\Users\user\projects\Skillfactory\Project News Portal\venv\Lib\site-packages\redis\connection.py", line 994, in _connect
    sock.connect(socket_address)
ConnectionRefusedError: [WinError 10061] Подключение не установлено, т.к. конечный компьютер отверг запрос на подключение

During handling of the above exception, another exception occurred:

Traceback (most recent call last):
  File "C:\Users\user\projects\Skillfactory\Project News Portal\venv\Lib\site-packages\kombu\connection.py", line 472, in _reraise_as_library_errors
    yield
  File "C:\Users\user\projects\Skillfactory\Project News Portal\venv\Lib\site-packages\celery\app\base.py", line 797, in send_task
    self.backend.on_task_call(P, task_id)
  File "C:\Users\user\projects\Skillfactory\Project News Portal\venv\Lib\site-packages\celery\backends\redis.py", line 373, in on_task_call
    self.result_consumer.consume_from(task_id)
  File "C:\Users\user\projects\Skillfactory\Project News Portal\venv\Lib\site-packages\celery\backends\redis.py", line 169, in consume_from
    return self.start(task_id)
           ^^^^^^^^^^^^^^^^^^^
  File "C:\Users\user\projects\Skillfactory\Project News Portal\venv\Lib\site-packages\celery\backends\redis.py", line 147, in start
    self._consume_from(initial_task_id)
  File "C:\Users\user\projects\Skillfactory\Project News Portal\venv\Lib\site-packages\celery\backends\redis.py", line 176, in _consume_from
    with self.reconnect_on_error():
  File "C:\Users\user\AppData\Local\Programs\Python\Python311\Lib\contextlib.py", line 155, in __exit__
    self.gen.throw(typ, value, traceback)
  File "C:\Users\user\projects\Skillfactory\Project News Portal\venv\Lib\site-packages\celery\backends\redis.py", line 130, in reconnect_on_error
    self._ensure(self._reconnect_pubsub, ())
  File "C:\Users\user\projects\Skillfactory\Project News Portal\venv\Lib\site-packages\celery\backends\redis.py", line 384, in ensure
    return retry_over_time(
           ^^^^^^^^^^^^^^^^
  File "C:\Users\user\projects\Skillfactory\Project News Portal\venv\Lib\site-packages\kombu\utils\functional.py", line 318, in retry_over_time
    return fun(*args, **kwargs)
           ^^^^^^^^^^^^^^^^^^^^
  File "C:\Users\user\projects\Skillfactory\Project News Portal\venv\Lib\site-packages\celery\backends\redis.py", line 106, in _reconnect_pubsub
    metas = self.backend.client.mget(self.subscribed_to)
            ^^^^^^^^^^^^^^^^^^^^^^^^^^^^^^^^^^^^^^^^^^^^
  File "C:\Users\user\projects\Skillfactory\Project News Portal\venv\Lib\site-packages\redis\commands\core.py", line 2002, in mget
    return self.execute_command("MGET", *args, **options)
           ^^^^^^^^^^^^^^^^^^^^^^^^^^^^^^^^^^^^^^^^^^^^^^
  File "C:\Users\user\projects\Skillfactory\Project News Portal\venv\Lib\site-packages\redis\client.py", line 1266, in execute_command
    conn = self.connection or pool.get_connection(command_name, **options)
                              ^^^^^^^^^^^^^^^^^^^^^^^^^^^^^^^^^^^^^^^^^^^^
  File "C:\Users\user\projects\Skillfactory\Project News Portal\venv\Lib\site-packages\redis\connection.py", line 1461, in get_connection
    connection.connect()
  File "C:\Users\user\projects\Skillfactory\Project News Portal\venv\Lib\site-packages\redis\connection.py", line 713, in connect
    raise ConnectionError(self._error_message(e))
redis.exceptions.ConnectionError: Error 10061 connecting to 127.0.0.1:6379. Подключение не установлено, т.к. конечный компьютер отверг запрос на подключение.

The above exception was the direct cause of the following exception:

Traceback (most recent call last):
  File "C:\Users\user\projects\Skillfactory\Project News Portal\venv\Lib\site-packages\django\core\handlers\exception.py", line 55, in inner
    response = get_response(request)
               ^^^^^^^^^^^^^^^^^^^^^
  File "C:\Users\user\projects\Skillfactory\Project News Portal\venv\Lib\site-packages\django\core\handlers\base.py", line 197, in _get_response
    response = wrapped_callback(request, *callback_args, **callback_kwargs)
               ^^^^^^^^^^^^^^^^^^^^^^^^^^^^^^^^^^^^^^^^^^^^^^^^^^^^^^^^^^^^
  File "C:\Users\user\projects\Skillfactory\Project News Portal\venv\Lib\site-packages\django\views\generic\base.py", line 104, in view
    return self.dispatch(request, *args, **kwargs)
           ^^^^^^^^^^^^^^^^^^^^^^^^^^^^^^^^^^^^^^^
  File "C:\Users\user\projects\Skillfactory\Project News Portal\venv\Lib\site-packages\django\contrib\auth\mixins.py", line 73, in dispatch
    return super().dispatch(request, *args, **kwargs)
           ^^^^^^^^^^^^^^^^^^^^^^^^^^^^^^^^^^^^^^^^^^
  File "C:\Users\user\projects\Skillfactory\Project News Portal\venv\Lib\site-packages\django\contrib\auth\mixins.py", line 109, in dispatch
    return super().dispatch(request, *args, **kwargs)
           ^^^^^^^^^^^^^^^^^^^^^^^^^^^^^^^^^^^^^^^^^^
  File "C:\Users\user\projects\Skillfactory\Project News Portal\venv\Lib\site-packages\django\views\generic\base.py", line 143, in dispatch
    return handler(request, *args, **kwargs)
           ^^^^^^^^^^^^^^^^^^^^^^^^^^^^^^^^^
  File "C:\Users\user\projects\Skillfactory\Project News Portal\News_Portal\news\views.py", line 60, in post
    notify_subscribers.delay(new_post.pk)   # вызов задачи на отправку письма подписчикам, при создании поста
    ^^^^^^^^^^^^^^^^^^^^^^^^^^^^^^^^^^^^^
  File "C:\Users\user\projects\Skillfactory\Project News Portal\venv\Lib\site-packages\celery\app\task.py", line 444, in delay
    return self.apply_async(args, kwargs)
           ^^^^^^^^^^^^^^^^^^^^^^^^^^^^^^
  File "C:\Users\user\projects\Skillfactory\Project News Portal\venv\Lib\site-packages\celery\app\task.py", line 594, in apply_async
    return app.send_task(
           ^^^^^^^^^^^^^^
  File "C:\Users\user\projects\Skillfactory\Project News Portal\venv\Lib\site-packages\celery\app\base.py", line 795, in send_task
    with P.connection._reraise_as_library_errors():
  File "C:\Users\user\AppData\Local\Programs\Python\Python311\Lib\contextlib.py", line 155, in __exit__
    self.gen.throw(typ, value, traceback)
  File "C:\Users\user\projects\Skillfactory\Project News Portal\venv\Lib\site-packages\kombu\connection.py", line 476, in _reraise_as_library_errors
    raise ConnectionError(str(exc)) from exc
kombu.exceptions.OperationalError: Error 10061 connecting to 127.0.0.1:6379. Подключение не установлено, т.к. конечный компьютер отверг запрос на подключение.
25.12.2023 20:41:39 [ERROR] Internal Server Error: /news/
C:\Users\user\projects\Skillfactory\Project News Portal\venv\Lib\site-packages\django\utils\log.py
(<class 'django.template.exceptions.TemplateSyntaxError'>, TemplateSyntaxError('Unknown argument for \'trans\' tag: \'capfirst\'. The only options available are \'noop\', \'context\' "xxx", and \'as VAR\'.'), <traceback object at 0x000002428498C600>)
Traceback (most recent call last):
  File "C:\Users\user\projects\Skillfactory\Project News Portal\venv\Lib\site-packages\django\core\handlers\exception.py", line 55, in inner
    response = get_response(request)
               ^^^^^^^^^^^^^^^^^^^^^
  File "C:\Users\user\projects\Skillfactory\Project News Portal\venv\Lib\site-packages\django\core\handlers\base.py", line 220, in _get_response
    response = response.render()
               ^^^^^^^^^^^^^^^^^
  File "C:\Users\user\projects\Skillfactory\Project News Portal\venv\Lib\site-packages\django\template\response.py", line 114, in render
    self.content = self.rendered_content
                   ^^^^^^^^^^^^^^^^^^^^^
  File "C:\Users\user\projects\Skillfactory\Project News Portal\venv\Lib\site-packages\django\template\response.py", line 92, in rendered_content
    return template.render(context, self._request)
           ^^^^^^^^^^^^^^^^^^^^^^^^^^^^^^^^^^^^^^^
  File "C:\Users\user\projects\Skillfactory\Project News Portal\venv\Lib\site-packages\django\template\backends\django.py", line 61, in render
    return self.template.render(context)
           ^^^^^^^^^^^^^^^^^^^^^^^^^^^^^
  File "C:\Users\user\projects\Skillfactory\Project News Portal\venv\Lib\site-packages\django\template\base.py", line 175, in render
    return self._render(context)
           ^^^^^^^^^^^^^^^^^^^^^
  File "C:\Users\user\projects\Skillfactory\Project News Portal\venv\Lib\site-packages\django\template\base.py", line 167, in _render
    return self.nodelist.render(context)
           ^^^^^^^^^^^^^^^^^^^^^^^^^^^^^
  File "C:\Users\user\projects\Skillfactory\Project News Portal\venv\Lib\site-packages\django\template\base.py", line 1005, in render
    return SafeString("".join([node.render_annotated(context) for node in self]))
                              ^^^^^^^^^^^^^^^^^^^^^^^^^^^^^^^^^^^^^^^^^^^^^^^^^
  File "C:\Users\user\projects\Skillfactory\Project News Portal\venv\Lib\site-packages\django\template\base.py", line 1005, in <listcomp>
    return SafeString("".join([node.render_annotated(context) for node in self]))
                               ^^^^^^^^^^^^^^^^^^^^^^^^^^^^^^
  File "C:\Users\user\projects\Skillfactory\Project News Portal\venv\Lib\site-packages\django\template\base.py", line 966, in render_annotated
    return self.render(context)
           ^^^^^^^^^^^^^^^^^^^^
  File "C:\Users\user\projects\Skillfactory\Project News Portal\venv\Lib\site-packages\django\template\loader_tags.py", line 132, in render
    compiled_parent = self.get_parent(context)
                      ^^^^^^^^^^^^^^^^^^^^^^^^
  File "C:\Users\user\projects\Skillfactory\Project News Portal\venv\Lib\site-packages\django\template\loader_tags.py", line 129, in get_parent
    return self.find_template(parent, context)
           ^^^^^^^^^^^^^^^^^^^^^^^^^^^^^^^^^^^
  File "C:\Users\user\projects\Skillfactory\Project News Portal\venv\Lib\site-packages\django\template\loader_tags.py", line 107, in find_template
    template, origin = context.template.engine.find_template(
                       ^^^^^^^^^^^^^^^^^^^^^^^^^^^^^^^^^^^^^^
  File "C:\Users\user\projects\Skillfactory\Project News Portal\venv\Lib\site-packages\django\template\engine.py", line 157, in find_template
    template = loader.get_template(name, skip=skip)
               ^^^^^^^^^^^^^^^^^^^^^^^^^^^^^^^^^^^^
  File "C:\Users\user\projects\Skillfactory\Project News Portal\venv\Lib\site-packages\django\template\loaders\cached.py", line 57, in get_template
    template = super().get_template(template_name, skip)
               ^^^^^^^^^^^^^^^^^^^^^^^^^^^^^^^^^^^^^^^^^
  File "C:\Users\user\projects\Skillfactory\Project News Portal\venv\Lib\site-packages\django\template\loaders\base.py", line 28, in get_template
    return Template(
           ^^^^^^^^^
  File "C:\Users\user\projects\Skillfactory\Project News Portal\venv\Lib\site-packages\django\template\base.py", line 154, in __init__
    self.nodelist = self.compile_nodelist()
                    ^^^^^^^^^^^^^^^^^^^^^^^
  File "C:\Users\user\projects\Skillfactory\Project News Portal\venv\Lib\site-packages\django\template\base.py", line 200, in compile_nodelist
    return parser.parse()
           ^^^^^^^^^^^^^^
  File "C:\Users\user\projects\Skillfactory\Project News Portal\venv\Lib\site-packages\django\template\base.py", line 513, in parse
    raise self.error(token, e)
  File "C:\Users\user\projects\Skillfactory\Project News Portal\venv\Lib\site-packages\django\template\base.py", line 511, in parse
    compiled_result = compile_func(self, token)
                      ^^^^^^^^^^^^^^^^^^^^^^^^^
  File "C:\Users\user\projects\Skillfactory\Project News Portal\venv\Lib\site-packages\django\templatetags\i18n.py", line 443, in do_translate
    raise TemplateSyntaxError(
django.template.exceptions.TemplateSyntaxError: Unknown argument for 'trans' tag: 'capfirst'. The only options available are 'noop', 'context' "xxx", and 'as VAR'.
25.12.2023 20:41:39 [ERROR] "GET /news/ HTTP/1.1" 500 208591
C:\Users\user\projects\Skillfactory\Project News Portal\venv\Lib\site-packages\django\core\servers\basehttp.py
None
25.12.2023 21:23:02 [ERROR] Internal Server Error: /news/6
C:\Users\user\projects\Skillfactory\Project News Portal\venv\Lib\site-packages\django\utils\log.py
(<class 'django.db.utils.OperationalError'>, OperationalError('no such column: news_post.title_ru'), <traceback object at 0x0000028A6E9DD140>)
Traceback (most recent call last):
  File "C:\Users\user\projects\Skillfactory\Project News Portal\venv\Lib\site-packages\django\db\backends\utils.py", line 89, in _execute
    return self.cursor.execute(sql, params)
           ^^^^^^^^^^^^^^^^^^^^^^^^^^^^^^^^
  File "C:\Users\user\projects\Skillfactory\Project News Portal\venv\Lib\site-packages\django\db\backends\sqlite3\base.py", line 328, in execute
    return super().execute(query, params)
           ^^^^^^^^^^^^^^^^^^^^^^^^^^^^^^
sqlite3.OperationalError: no such column: news_post.title_ru

The above exception was the direct cause of the following exception:

Traceback (most recent call last):
  File "C:\Users\user\projects\Skillfactory\Project News Portal\venv\Lib\site-packages\django\core\handlers\exception.py", line 55, in inner
    response = get_response(request)
               ^^^^^^^^^^^^^^^^^^^^^
  File "C:\Users\user\projects\Skillfactory\Project News Portal\venv\Lib\site-packages\django\core\handlers\base.py", line 197, in _get_response
    response = wrapped_callback(request, *callback_args, **callback_kwargs)
               ^^^^^^^^^^^^^^^^^^^^^^^^^^^^^^^^^^^^^^^^^^^^^^^^^^^^^^^^^^^^
  File "C:\Users\user\projects\Skillfactory\Project News Portal\venv\Lib\site-packages\django\views\generic\base.py", line 104, in view
    return self.dispatch(request, *args, **kwargs)
           ^^^^^^^^^^^^^^^^^^^^^^^^^^^^^^^^^^^^^^^
  File "C:\Users\user\projects\Skillfactory\Project News Portal\venv\Lib\site-packages\django\views\generic\base.py", line 143, in dispatch
    return handler(request, *args, **kwargs)
           ^^^^^^^^^^^^^^^^^^^^^^^^^^^^^^^^^
  File "C:\Users\user\projects\Skillfactory\Project News Portal\venv\Lib\site-packages\django\views\generic\detail.py", line 108, in get
    self.object = self.get_object()
                  ^^^^^^^^^^^^^^^^^
  File "C:\Users\user\projects\Skillfactory\Project News Portal\venv\Lib\site-packages\django\views\generic\detail.py", line 53, in get_object
    obj = queryset.get()
          ^^^^^^^^^^^^^^
  File "C:\Users\user\projects\Skillfactory\Project News Portal\venv\Lib\site-packages\django\db\models\query.py", line 633, in get
    num = len(clone)
          ^^^^^^^^^^
  File "C:\Users\user\projects\Skillfactory\Project News Portal\venv\Lib\site-packages\django\db\models\query.py", line 380, in __len__
    self._fetch_all()
  File "C:\Users\user\projects\Skillfactory\Project News Portal\venv\Lib\site-packages\django\db\models\query.py", line 1881, in _fetch_all
    self._result_cache = list(self._iterable_class(self))
                         ^^^^^^^^^^^^^^^^^^^^^^^^^^^^^^^^
  File "C:\Users\user\projects\Skillfactory\Project News Portal\venv\Lib\site-packages\django\db\models\query.py", line 91, in __iter__
    results = compiler.execute_sql(
              ^^^^^^^^^^^^^^^^^^^^^
  File "C:\Users\user\projects\Skillfactory\Project News Portal\venv\Lib\site-packages\django\db\models\sql\compiler.py", line 1562, in execute_sql
    cursor.execute(sql, params)
  File "C:\Users\user\projects\Skillfactory\Project News Portal\venv\Lib\site-packages\django\db\backends\utils.py", line 102, in execute
    return super().execute(sql, params)
           ^^^^^^^^^^^^^^^^^^^^^^^^^^^^
  File "C:\Users\user\projects\Skillfactory\Project News Portal\venv\Lib\site-packages\django\db\backends\utils.py", line 67, in execute
    return self._execute_with_wrappers(
           ^^^^^^^^^^^^^^^^^^^^^^^^^^^^
  File "C:\Users\user\projects\Skillfactory\Project News Portal\venv\Lib\site-packages\django\db\backends\utils.py", line 80, in _execute_with_wrappers
    return executor(sql, params, many, context)
           ^^^^^^^^^^^^^^^^^^^^^^^^^^^^^^^^^^^^
  File "C:\Users\user\projects\Skillfactory\Project News Portal\venv\Lib\site-packages\django\db\backends\utils.py", line 84, in _execute
    with self.db.wrap_database_errors:
  File "C:\Users\user\projects\Skillfactory\Project News Portal\venv\Lib\site-packages\django\db\utils.py", line 91, in __exit__
    raise dj_exc_value.with_traceback(traceback) from exc_value
  File "C:\Users\user\projects\Skillfactory\Project News Portal\venv\Lib\site-packages\django\db\backends\utils.py", line 89, in _execute
    return self.cursor.execute(sql, params)
           ^^^^^^^^^^^^^^^^^^^^^^^^^^^^^^^^
  File "C:\Users\user\projects\Skillfactory\Project News Portal\venv\Lib\site-packages\django\db\backends\sqlite3\base.py", line 328, in execute
    return super().execute(query, params)
           ^^^^^^^^^^^^^^^^^^^^^^^^^^^^^^
django.db.utils.OperationalError: no such column: news_post.title_ru
25.12.2023 21:23:02 [ERROR] "GET /news/6 HTTP/1.1" 500 156028
C:\Users\user\projects\Skillfactory\Project News Portal\venv\Lib\site-packages\django\core\servers\basehttp.py
None
25.12.2023 21:23:24 [ERROR] Internal Server Error: /news/5
C:\Users\user\projects\Skillfactory\Project News Portal\venv\Lib\site-packages\django\utils\log.py
(<class 'django.db.utils.OperationalError'>, OperationalError('no such column: news_post.title_ru'), <traceback object at 0x0000028A6E753C00>)
Traceback (most recent call last):
  File "C:\Users\user\projects\Skillfactory\Project News Portal\venv\Lib\site-packages\django\db\backends\utils.py", line 89, in _execute
    return self.cursor.execute(sql, params)
           ^^^^^^^^^^^^^^^^^^^^^^^^^^^^^^^^
  File "C:\Users\user\projects\Skillfactory\Project News Portal\venv\Lib\site-packages\django\db\backends\sqlite3\base.py", line 328, in execute
    return super().execute(query, params)
           ^^^^^^^^^^^^^^^^^^^^^^^^^^^^^^
sqlite3.OperationalError: no such column: news_post.title_ru

The above exception was the direct cause of the following exception:

Traceback (most recent call last):
  File "C:\Users\user\projects\Skillfactory\Project News Portal\venv\Lib\site-packages\django\core\handlers\exception.py", line 55, in inner
    response = get_response(request)
               ^^^^^^^^^^^^^^^^^^^^^
  File "C:\Users\user\projects\Skillfactory\Project News Portal\venv\Lib\site-packages\django\core\handlers\base.py", line 197, in _get_response
    response = wrapped_callback(request, *callback_args, **callback_kwargs)
               ^^^^^^^^^^^^^^^^^^^^^^^^^^^^^^^^^^^^^^^^^^^^^^^^^^^^^^^^^^^^
  File "C:\Users\user\projects\Skillfactory\Project News Portal\venv\Lib\site-packages\django\views\generic\base.py", line 104, in view
    return self.dispatch(request, *args, **kwargs)
           ^^^^^^^^^^^^^^^^^^^^^^^^^^^^^^^^^^^^^^^
  File "C:\Users\user\projects\Skillfactory\Project News Portal\venv\Lib\site-packages\django\views\generic\base.py", line 143, in dispatch
    return handler(request, *args, **kwargs)
           ^^^^^^^^^^^^^^^^^^^^^^^^^^^^^^^^^
  File "C:\Users\user\projects\Skillfactory\Project News Portal\venv\Lib\site-packages\django\views\generic\detail.py", line 108, in get
    self.object = self.get_object()
                  ^^^^^^^^^^^^^^^^^
  File "C:\Users\user\projects\Skillfactory\Project News Portal\venv\Lib\site-packages\django\views\generic\detail.py", line 53, in get_object
    obj = queryset.get()
          ^^^^^^^^^^^^^^
  File "C:\Users\user\projects\Skillfactory\Project News Portal\venv\Lib\site-packages\django\db\models\query.py", line 633, in get
    num = len(clone)
          ^^^^^^^^^^
  File "C:\Users\user\projects\Skillfactory\Project News Portal\venv\Lib\site-packages\django\db\models\query.py", line 380, in __len__
    self._fetch_all()
  File "C:\Users\user\projects\Skillfactory\Project News Portal\venv\Lib\site-packages\django\db\models\query.py", line 1881, in _fetch_all
    self._result_cache = list(self._iterable_class(self))
                         ^^^^^^^^^^^^^^^^^^^^^^^^^^^^^^^^
  File "C:\Users\user\projects\Skillfactory\Project News Portal\venv\Lib\site-packages\django\db\models\query.py", line 91, in __iter__
    results = compiler.execute_sql(
              ^^^^^^^^^^^^^^^^^^^^^
  File "C:\Users\user\projects\Skillfactory\Project News Portal\venv\Lib\site-packages\django\db\models\sql\compiler.py", line 1562, in execute_sql
    cursor.execute(sql, params)
  File "C:\Users\user\projects\Skillfactory\Project News Portal\venv\Lib\site-packages\django\db\backends\utils.py", line 102, in execute
    return super().execute(sql, params)
           ^^^^^^^^^^^^^^^^^^^^^^^^^^^^
  File "C:\Users\user\projects\Skillfactory\Project News Portal\venv\Lib\site-packages\django\db\backends\utils.py", line 67, in execute
    return self._execute_with_wrappers(
           ^^^^^^^^^^^^^^^^^^^^^^^^^^^^
  File "C:\Users\user\projects\Skillfactory\Project News Portal\venv\Lib\site-packages\django\db\backends\utils.py", line 80, in _execute_with_wrappers
    return executor(sql, params, many, context)
           ^^^^^^^^^^^^^^^^^^^^^^^^^^^^^^^^^^^^
  File "C:\Users\user\projects\Skillfactory\Project News Portal\venv\Lib\site-packages\django\db\backends\utils.py", line 84, in _execute
    with self.db.wrap_database_errors:
  File "C:\Users\user\projects\Skillfactory\Project News Portal\venv\Lib\site-packages\django\db\utils.py", line 91, in __exit__
    raise dj_exc_value.with_traceback(traceback) from exc_value
  File "C:\Users\user\projects\Skillfactory\Project News Portal\venv\Lib\site-packages\django\db\backends\utils.py", line 89, in _execute
    return self.cursor.execute(sql, params)
           ^^^^^^^^^^^^^^^^^^^^^^^^^^^^^^^^
  File "C:\Users\user\projects\Skillfactory\Project News Portal\venv\Lib\site-packages\django\db\backends\sqlite3\base.py", line 328, in execute
    return super().execute(query, params)
           ^^^^^^^^^^^^^^^^^^^^^^^^^^^^^^
django.db.utils.OperationalError: no such column: news_post.title_ru
25.12.2023 21:23:24 [ERROR] "GET /news/5 HTTP/1.1" 500 156028
C:\Users\user\projects\Skillfactory\Project News Portal\venv\Lib\site-packages\django\core\servers\basehttp.py
None
25.12.2023 22:38:36 [ERROR] Internal Server Error: /news/
C:\Users\user\projects\Skillfactory\Project News Portal\venv\Lib\site-packages\django\utils\log.py
(<class 'AttributeError'>, AttributeError("'dict' object has no attribute 'status_code'"), <traceback object at 0x0000027A47000540>)
Traceback (most recent call last):
  File "C:\Users\user\projects\Skillfactory\Project News Portal\venv\Lib\site-packages\django\core\handlers\exception.py", line 55, in inner
    response = get_response(request)
               ^^^^^^^^^^^^^^^^^^^^^
  File "C:\Users\user\projects\Skillfactory\Project News Portal\venv\Lib\site-packages\django\utils\deprecation.py", line 136, in __call__
    response = self.process_response(request, response)
               ^^^^^^^^^^^^^^^^^^^^^^^^^^^^^^^^^^^^^^^^
  File "C:\Users\user\projects\Skillfactory\Project News Portal\venv\Lib\site-packages\django\middleware\locale.py", line 48, in process_response
    response.status_code == 404
    ^^^^^^^^^^^^^^^^^^^^
AttributeError: 'dict' object has no attribute 'status_code'
25.12.2023 22:38:36 [ERROR] "GET /news/ HTTP/1.1" 500 84899
C:\Users\user\projects\Skillfactory\Project News Portal\venv\Lib\site-packages\django\core\servers\basehttp.py
None
25.12.2023 22:38:42 [ERROR] Internal Server Error: /news/
C:\Users\user\projects\Skillfactory\Project News Portal\venv\Lib\site-packages\django\utils\log.py
(<class 'AttributeError'>, AttributeError("'dict' object has no attribute 'status_code'"), <traceback object at 0x0000027A47002FC0>)
Traceback (most recent call last):
  File "C:\Users\user\projects\Skillfactory\Project News Portal\venv\Lib\site-packages\django\core\handlers\exception.py", line 55, in inner
    response = get_response(request)
               ^^^^^^^^^^^^^^^^^^^^^
  File "C:\Users\user\projects\Skillfactory\Project News Portal\venv\Lib\site-packages\django\utils\deprecation.py", line 136, in __call__
    response = self.process_response(request, response)
               ^^^^^^^^^^^^^^^^^^^^^^^^^^^^^^^^^^^^^^^^
  File "C:\Users\user\projects\Skillfactory\Project News Portal\venv\Lib\site-packages\django\middleware\locale.py", line 48, in process_response
    response.status_code == 404
    ^^^^^^^^^^^^^^^^^^^^
AttributeError: 'dict' object has no attribute 'status_code'
25.12.2023 22:38:42 [ERROR] "GET /news/ HTTP/1.1" 500 84899
C:\Users\user\projects\Skillfactory\Project News Portal\venv\Lib\site-packages\django\core\servers\basehttp.py
None
25.12.2023 23:50:18 [ERROR] Internal Server Error: /news/
C:\Users\user\projects\Skillfactory\Project News Portal\venv\Lib\site-packages\django\utils\log.py
(<class 'TypeError'>, TypeError('context must be a dict rather than tuple.'), <traceback object at 0x000002383EE5EAC0>)
Traceback (most recent call last):
  File "C:\Users\user\projects\Skillfactory\Project News Portal\venv\Lib\site-packages\django\core\handlers\exception.py", line 55, in inner
    response = get_response(request)
               ^^^^^^^^^^^^^^^^^^^^^
  File "C:\Users\user\projects\Skillfactory\Project News Portal\venv\Lib\site-packages\django\core\handlers\base.py", line 220, in _get_response
    response = response.render()
               ^^^^^^^^^^^^^^^^^
  File "C:\Users\user\projects\Skillfactory\Project News Portal\venv\Lib\site-packages\django\template\response.py", line 114, in render
    self.content = self.rendered_content
                   ^^^^^^^^^^^^^^^^^^^^^
  File "C:\Users\user\projects\Skillfactory\Project News Portal\venv\Lib\site-packages\django\template\response.py", line 92, in rendered_content
    return template.render(context, self._request)
           ^^^^^^^^^^^^^^^^^^^^^^^^^^^^^^^^^^^^^^^
  File "C:\Users\user\projects\Skillfactory\Project News Portal\venv\Lib\site-packages\django\template\backends\django.py", line 57, in render
    context = make_context(
              ^^^^^^^^^^^^^
  File "C:\Users\user\projects\Skillfactory\Project News Portal\venv\Lib\site-packages\django\template\context.py", line 278, in make_context
    raise TypeError(
TypeError: context must be a dict rather than tuple.
25.12.2023 23:50:18 [ERROR] "GET /news/?timezone=GMT HTTP/1.1" 500 89753
C:\Users\user\projects\Skillfactory\Project News Portal\venv\Lib\site-packages\django\core\servers\basehttp.py
None
25.12.2023 23:50:39 [ERROR] Internal Server Error: /news/
C:\Users\user\projects\Skillfactory\Project News Portal\venv\Lib\site-packages\django\utils\log.py
(<class 'TypeError'>, TypeError('context must be a dict rather than tuple.'), <traceback object at 0x0000022471D52780>)
Traceback (most recent call last):
  File "C:\Users\user\projects\Skillfactory\Project News Portal\venv\Lib\site-packages\django\core\handlers\exception.py", line 55, in inner
    response = get_response(request)
               ^^^^^^^^^^^^^^^^^^^^^
  File "C:\Users\user\projects\Skillfactory\Project News Portal\venv\Lib\site-packages\django\core\handlers\base.py", line 220, in _get_response
    response = response.render()
               ^^^^^^^^^^^^^^^^^
  File "C:\Users\user\projects\Skillfactory\Project News Portal\venv\Lib\site-packages\django\template\response.py", line 114, in render
    self.content = self.rendered_content
                   ^^^^^^^^^^^^^^^^^^^^^
  File "C:\Users\user\projects\Skillfactory\Project News Portal\venv\Lib\site-packages\django\template\response.py", line 92, in rendered_content
    return template.render(context, self._request)
           ^^^^^^^^^^^^^^^^^^^^^^^^^^^^^^^^^^^^^^^
  File "C:\Users\user\projects\Skillfactory\Project News Portal\venv\Lib\site-packages\django\template\backends\django.py", line 57, in render
    context = make_context(
              ^^^^^^^^^^^^^
  File "C:\Users\user\projects\Skillfactory\Project News Portal\venv\Lib\site-packages\django\template\context.py", line 278, in make_context
    raise TypeError(
TypeError: context must be a dict rather than tuple.
25.12.2023 23:50:39 [ERROR] "GET /news/?timezone=GMT HTTP/1.1" 500 89753
C:\Users\user\projects\Skillfactory\Project News Portal\venv\Lib\site-packages\django\core\servers\basehttp.py
None
26.12.2023 00:07:40 [ERROR] Internal Server Error: /news/5
C:\Users\user\projects\Skillfactory\Project News Portal\venv\Lib\site-packages\django\utils\log.py
(<class 'django.template.exceptions.TemplateSyntaxError'>, TemplateSyntaxError("Invalid block tag on line 25: 'trans', expected 'endblock'. Did you forget to register or load this tag?"), <traceback object at 0x0000023CBFC8EA80>)
Traceback (most recent call last):
  File "C:\Users\user\projects\Skillfactory\Project News Portal\venv\Lib\site-packages\django\template\base.py", line 505, in parse
    compile_func = self.tags[command]
                   ~~~~~~~~~^^^^^^^^^
KeyError: 'trans'

During handling of the above exception, another exception occurred:

Traceback (most recent call last):
  File "C:\Users\user\projects\Skillfactory\Project News Portal\venv\Lib\site-packages\django\core\handlers\exception.py", line 55, in inner
    response = get_response(request)
               ^^^^^^^^^^^^^^^^^^^^^
  File "C:\Users\user\projects\Skillfactory\Project News Portal\venv\Lib\site-packages\django\core\handlers\base.py", line 220, in _get_response
    response = response.render()
               ^^^^^^^^^^^^^^^^^
  File "C:\Users\user\projects\Skillfactory\Project News Portal\venv\Lib\site-packages\django\template\response.py", line 114, in render
    self.content = self.rendered_content
                   ^^^^^^^^^^^^^^^^^^^^^
  File "C:\Users\user\projects\Skillfactory\Project News Portal\venv\Lib\site-packages\django\template\response.py", line 90, in rendered_content
    template = self.resolve_template(self.template_name)
               ^^^^^^^^^^^^^^^^^^^^^^^^^^^^^^^^^^^^^^^^^
  File "C:\Users\user\projects\Skillfactory\Project News Portal\venv\Lib\site-packages\django\template\response.py", line 72, in resolve_template
    return select_template(template, using=self.using)
           ^^^^^^^^^^^^^^^^^^^^^^^^^^^^^^^^^^^^^^^^^^^
  File "C:\Users\user\projects\Skillfactory\Project News Portal\venv\Lib\site-packages\django\template\loader.py", line 42, in select_template
    return engine.get_template(template_name)
           ^^^^^^^^^^^^^^^^^^^^^^^^^^^^^^^^^^
  File "C:\Users\user\projects\Skillfactory\Project News Portal\venv\Lib\site-packages\django\template\backends\django.py", line 33, in get_template
    return Template(self.engine.get_template(template_name), self)
                    ^^^^^^^^^^^^^^^^^^^^^^^^^^^^^^^^^^^^^^^
  File "C:\Users\user\projects\Skillfactory\Project News Portal\venv\Lib\site-packages\django\template\engine.py", line 175, in get_template
    template, origin = self.find_template(template_name)
                       ^^^^^^^^^^^^^^^^^^^^^^^^^^^^^^^^^
  File "C:\Users\user\projects\Skillfactory\Project News Portal\venv\Lib\site-packages\django\template\engine.py", line 157, in find_template
    template = loader.get_template(name, skip=skip)
               ^^^^^^^^^^^^^^^^^^^^^^^^^^^^^^^^^^^^
  File "C:\Users\user\projects\Skillfactory\Project News Portal\venv\Lib\site-packages\django\template\loaders\cached.py", line 57, in get_template
    template = super().get_template(template_name, skip)
               ^^^^^^^^^^^^^^^^^^^^^^^^^^^^^^^^^^^^^^^^^
  File "C:\Users\user\projects\Skillfactory\Project News Portal\venv\Lib\site-packages\django\template\loaders\base.py", line 28, in get_template
    return Template(
           ^^^^^^^^^
  File "C:\Users\user\projects\Skillfactory\Project News Portal\venv\Lib\site-packages\django\template\base.py", line 154, in __init__
    self.nodelist = self.compile_nodelist()
                    ^^^^^^^^^^^^^^^^^^^^^^^
  File "C:\Users\user\projects\Skillfactory\Project News Portal\venv\Lib\site-packages\django\template\base.py", line 200, in compile_nodelist
    return parser.parse()
           ^^^^^^^^^^^^^^
  File "C:\Users\user\projects\Skillfactory\Project News Portal\venv\Lib\site-packages\django\template\base.py", line 513, in parse
    raise self.error(token, e)
  File "C:\Users\user\projects\Skillfactory\Project News Portal\venv\Lib\site-packages\django\template\base.py", line 511, in parse
    compiled_result = compile_func(self, token)
                      ^^^^^^^^^^^^^^^^^^^^^^^^^
  File "C:\Users\user\projects\Skillfactory\Project News Portal\venv\Lib\site-packages\django\template\loader_tags.py", line 293, in do_extends
    nodelist = parser.parse()
               ^^^^^^^^^^^^^^
  File "C:\Users\user\projects\Skillfactory\Project News Portal\venv\Lib\site-packages\django\template\base.py", line 513, in parse
    raise self.error(token, e)
  File "C:\Users\user\projects\Skillfactory\Project News Portal\venv\Lib\site-packages\django\template\base.py", line 511, in parse
    compiled_result = compile_func(self, token)
                      ^^^^^^^^^^^^^^^^^^^^^^^^^
  File "C:\Users\user\projects\Skillfactory\Project News Portal\venv\Lib\site-packages\django\template\loader_tags.py", line 232, in do_block
    nodelist = parser.parse(("endblock",))
               ^^^^^^^^^^^^^^^^^^^^^^^^^^^
  File "C:\Users\user\projects\Skillfactory\Project News Portal\venv\Lib\site-packages\django\template\base.py", line 507, in parse
    self.invalid_block_tag(token, command, parse_until)
  File "C:\Users\user\projects\Skillfactory\Project News Portal\venv\Lib\site-packages\django\template\base.py", line 558, in invalid_block_tag
    raise self.error(
django.template.exceptions.TemplateSyntaxError: Invalid block tag on line 25: 'trans', expected 'endblock'. Did you forget to register or load this tag?
26.12.2023 00:07:40 [ERROR] "GET /news/5 HTTP/1.1" 500 200867
C:\Users\user\projects\Skillfactory\Project News Portal\venv\Lib\site-packages\django\core\servers\basehttp.py
None
26.12.2023 00:52:26 [ERROR] Internal Server Error: /news/2/subscription_category
C:\Users\user\projects\Skillfactory\Project News Portal\venv\Lib\site-packages\django\utils\log.py
(<class 'TypeError'>, TypeError("BaseContextMixin.subscribe_category() missing 1 required positional argument: 'request'"), <traceback object at 0x0000029D79B1D340>)
Traceback (most recent call last):
  File "C:\Users\user\projects\Skillfactory\Project News Portal\venv\Lib\site-packages\django\core\handlers\exception.py", line 55, in inner
    response = get_response(request)
               ^^^^^^^^^^^^^^^^^^^^^
  File "C:\Users\user\projects\Skillfactory\Project News Portal\venv\Lib\site-packages\django\core\handlers\base.py", line 197, in _get_response
    response = wrapped_callback(request, *callback_args, **callback_kwargs)
               ^^^^^^^^^^^^^^^^^^^^^^^^^^^^^^^^^^^^^^^^^^^^^^^^^^^^^^^^^^^^
  File "C:\Users\user\projects\Skillfactory\Project News Portal\venv\Lib\site-packages\django\contrib\auth\decorators.py", line 23, in _wrapper_view
    return view_func(request, *args, **kwargs)
           ^^^^^^^^^^^^^^^^^^^^^^^^^^^^^^^^^^^
TypeError: BaseContextMixin.subscribe_category() missing 1 required positional argument: 'request'
26.12.2023 00:52:26 [ERROR] "GET /news/2/subscription_category?selected_category=%D0%A0%D0%B5%D1%86%D0%B5%D0%BF%D1%82%D1%8B HTTP/1.1" 500 76874
C:\Users\user\projects\Skillfactory\Project News Portal\venv\Lib\site-packages\django\core\servers\basehttp.py
None
26.12.2023 01:00:48 [ERROR] Internal Server Error: /news/2/subscription_category
C:\Users\user\projects\Skillfactory\Project News Portal\venv\Lib\site-packages\django\utils\log.py
(<class 'TypeError'>, TypeError("SubscribeView.subscribe_category() missing 1 required positional argument: 'request'"), <traceback object at 0x000001AA3A302840>)
Traceback (most recent call last):
  File "C:\Users\user\projects\Skillfactory\Project News Portal\venv\Lib\site-packages\django\core\handlers\exception.py", line 55, in inner
    response = get_response(request)
               ^^^^^^^^^^^^^^^^^^^^^
  File "C:\Users\user\projects\Skillfactory\Project News Portal\venv\Lib\site-packages\django\core\handlers\base.py", line 197, in _get_response
    response = wrapped_callback(request, *callback_args, **callback_kwargs)
               ^^^^^^^^^^^^^^^^^^^^^^^^^^^^^^^^^^^^^^^^^^^^^^^^^^^^^^^^^^^^
  File "C:\Users\user\projects\Skillfactory\Project News Portal\venv\Lib\site-packages\django\contrib\auth\decorators.py", line 23, in _wrapper_view
    return view_func(request, *args, **kwargs)
           ^^^^^^^^^^^^^^^^^^^^^^^^^^^^^^^^^^^
TypeError: SubscribeView.subscribe_category() missing 1 required positional argument: 'request'
26.12.2023 01:00:48 [ERROR] "GET /news/2/subscription_category?selected_category=%D0%A0%D0%B5%D1%86%D0%B5%D0%BF%D1%82%D1%8B HTTP/1.1" 500 76853
C:\Users\user\projects\Skillfactory\Project News Portal\venv\Lib\site-packages\django\core\servers\basehttp.py
None
26.12.2023 01:03:33 [ERROR] Internal Server Error: /news/2/subscription_category
C:\Users\user\projects\Skillfactory\Project News Portal\venv\Lib\site-packages\django\utils\log.py
(<class 'TypeError'>, TypeError("SubscribeView.subscribe_category() missing 1 required positional argument: 'request'"), <traceback object at 0x0000024B758DFA00>)
Traceback (most recent call last):
  File "C:\Users\user\projects\Skillfactory\Project News Portal\venv\Lib\site-packages\django\core\handlers\exception.py", line 55, in inner
    response = get_response(request)
               ^^^^^^^^^^^^^^^^^^^^^
  File "C:\Users\user\projects\Skillfactory\Project News Portal\venv\Lib\site-packages\django\core\handlers\base.py", line 197, in _get_response
    response = wrapped_callback(request, *callback_args, **callback_kwargs)
               ^^^^^^^^^^^^^^^^^^^^^^^^^^^^^^^^^^^^^^^^^^^^^^^^^^^^^^^^^^^^
TypeError: SubscribeView.subscribe_category() missing 1 required positional argument: 'request'
26.12.2023 01:03:33 [ERROR] "GET /news/2/subscription_category?selected_category=%D0%A0%D0%B5%D1%86%D0%B5%D0%BF%D1%82%D1%8B HTTP/1.1" 500 71661
C:\Users\user\projects\Skillfactory\Project News Portal\venv\Lib\site-packages\django\core\servers\basehttp.py
None
26.12.2023 01:24:56 [ERROR] Internal Server Error: /news/2/subscription_category
C:\Users\user\projects\Skillfactory\Project News Portal\venv\Lib\site-packages\django\utils\log.py
(<class 'django.urls.exceptions.NoReverseMatch'>, NoReverseMatch("Reverse for 'redirect_to_sections' not found. 'redirect_to_sections' is not a valid view function or pattern name."), <traceback object at 0x000002B365AC0340>)
Traceback (most recent call last):
  File "C:\Users\user\projects\Skillfactory\Project News Portal\venv\Lib\site-packages\django\core\handlers\exception.py", line 55, in inner
    response = get_response(request)
               ^^^^^^^^^^^^^^^^^^^^^
  File "C:\Users\user\projects\Skillfactory\Project News Portal\venv\Lib\site-packages\django\core\handlers\base.py", line 197, in _get_response
    response = wrapped_callback(request, *callback_args, **callback_kwargs)
               ^^^^^^^^^^^^^^^^^^^^^^^^^^^^^^^^^^^^^^^^^^^^^^^^^^^^^^^^^^^^
  File "C:\Users\user\projects\Skillfactory\Project News Portal\venv\Lib\site-packages\django\contrib\auth\decorators.py", line 23, in _wrapper_view
    return view_func(request, *args, **kwargs)
           ^^^^^^^^^^^^^^^^^^^^^^^^^^^^^^^^^^^
  File "C:\Users\user\projects\Skillfactory\Project News Portal\News_Portal\news\views.py", line 140, in subscribe_category
    return render(request, 'subscription_category.html', {'redirect_to': reverse('redirect_to_sections')})
                                                                         ^^^^^^^^^^^^^^^^^^^^^^^^^^^^^^^
  File "C:\Users\user\projects\Skillfactory\Project News Portal\venv\Lib\site-packages\django\urls\base.py", line 88, in reverse
    return resolver._reverse_with_prefix(view, prefix, *args, **kwargs)
           ^^^^^^^^^^^^^^^^^^^^^^^^^^^^^^^^^^^^^^^^^^^^^^^^^^^^^^^^^^^^
  File "C:\Users\user\projects\Skillfactory\Project News Portal\venv\Lib\site-packages\django\urls\resolvers.py", line 828, in _reverse_with_prefix
    raise NoReverseMatch(msg)
django.urls.exceptions.NoReverseMatch: Reverse for 'redirect_to_sections' not found. 'redirect_to_sections' is not a valid view function or pattern name.
26.12.2023 01:24:56 [ERROR] "GET /news/2/subscription_category?selected_category=%D0%A0%D0%B5%D1%86%D0%B5%D0%BF%D1%82%D1%8B HTTP/1.1" 500 91543
C:\Users\user\projects\Skillfactory\Project News Portal\venv\Lib\site-packages\django\core\servers\basehttp.py
None
26.12.2023 01:25:45 [ERROR] Internal Server Error: /news/2/subscription_category
C:\Users\user\projects\Skillfactory\Project News Portal\venv\Lib\site-packages\django\utils\log.py
(<class 'django.urls.exceptions.NoReverseMatch'>, NoReverseMatch("Reverse for 'categories' not found. 'categories' is not a valid view function or pattern name."), <traceback object at 0x000002C2EA9A9F80>)
Traceback (most recent call last):
  File "C:\Users\user\projects\Skillfactory\Project News Portal\venv\Lib\site-packages\django\core\handlers\exception.py", line 55, in inner
    response = get_response(request)
               ^^^^^^^^^^^^^^^^^^^^^
  File "C:\Users\user\projects\Skillfactory\Project News Portal\venv\Lib\site-packages\django\core\handlers\base.py", line 197, in _get_response
    response = wrapped_callback(request, *callback_args, **callback_kwargs)
               ^^^^^^^^^^^^^^^^^^^^^^^^^^^^^^^^^^^^^^^^^^^^^^^^^^^^^^^^^^^^
  File "C:\Users\user\projects\Skillfactory\Project News Portal\venv\Lib\site-packages\django\contrib\auth\decorators.py", line 23, in _wrapper_view
    return view_func(request, *args, **kwargs)
           ^^^^^^^^^^^^^^^^^^^^^^^^^^^^^^^^^^^
  File "C:\Users\user\projects\Skillfactory\Project News Portal\News_Portal\news\views.py", line 140, in subscribe_category
    return render(request, 'subscription_category.html', {'redirect_to': reverse('categories')})
                                                                         ^^^^^^^^^^^^^^^^^^^^^
  File "C:\Users\user\projects\Skillfactory\Project News Portal\venv\Lib\site-packages\django\urls\base.py", line 88, in reverse
    return resolver._reverse_with_prefix(view, prefix, *args, **kwargs)
           ^^^^^^^^^^^^^^^^^^^^^^^^^^^^^^^^^^^^^^^^^^^^^^^^^^^^^^^^^^^^
  File "C:\Users\user\projects\Skillfactory\Project News Portal\venv\Lib\site-packages\django\urls\resolvers.py", line 828, in _reverse_with_prefix
    raise NoReverseMatch(msg)
django.urls.exceptions.NoReverseMatch: Reverse for 'categories' not found. 'categories' is not a valid view function or pattern name.
26.12.2023 01:25:45 [ERROR] "GET /news/2/subscription_category?selected_category=%D0%A0%D0%B5%D1%86%D0%B5%D0%BF%D1%82%D1%8B HTTP/1.1" 500 91418
C:\Users\user\projects\Skillfactory\Project News Portal\venv\Lib\site-packages\django\core\servers\basehttp.py
None
26.12.2023 01:26:57 [ERROR] Internal Server Error: /news/2/subscription_category
C:\Users\user\projects\Skillfactory\Project News Portal\venv\Lib\site-packages\django\utils\log.py
(<class 'django.urls.exceptions.NoReverseMatch'>, NoReverseMatch("Reverse for 'redirect_to_sections' not found. 'redirect_to_sections' is not a valid view function or pattern name."), <traceback object at 0x0000019EC3226200>)
Traceback (most recent call last):
  File "C:\Users\user\projects\Skillfactory\Project News Portal\venv\Lib\site-packages\django\core\handlers\exception.py", line 55, in inner
    response = get_response(request)
               ^^^^^^^^^^^^^^^^^^^^^
  File "C:\Users\user\projects\Skillfactory\Project News Portal\venv\Lib\site-packages\django\core\handlers\base.py", line 197, in _get_response
    response = wrapped_callback(request, *callback_args, **callback_kwargs)
               ^^^^^^^^^^^^^^^^^^^^^^^^^^^^^^^^^^^^^^^^^^^^^^^^^^^^^^^^^^^^
  File "C:\Users\user\projects\Skillfactory\Project News Portal\venv\Lib\site-packages\django\contrib\auth\decorators.py", line 23, in _wrapper_view
    return view_func(request, *args, **kwargs)
           ^^^^^^^^^^^^^^^^^^^^^^^^^^^^^^^^^^^
  File "C:\Users\user\projects\Skillfactory\Project News Portal\News_Portal\news\views.py", line 145, in subscribe_category
    return render(request, 'subscription_category.html', {'redirect_to': reverse('redirect_to_sections')})
                                                                         ^^^^^^^^^^^^^^^^^^^^^^^^^^^^^^^
  File "C:\Users\user\projects\Skillfactory\Project News Portal\venv\Lib\site-packages\django\urls\base.py", line 88, in reverse
    return resolver._reverse_with_prefix(view, prefix, *args, **kwargs)
           ^^^^^^^^^^^^^^^^^^^^^^^^^^^^^^^^^^^^^^^^^^^^^^^^^^^^^^^^^^^^
  File "C:\Users\user\projects\Skillfactory\Project News Portal\venv\Lib\site-packages\django\urls\resolvers.py", line 828, in _reverse_with_prefix
    raise NoReverseMatch(msg)
django.urls.exceptions.NoReverseMatch: Reverse for 'redirect_to_sections' not found. 'redirect_to_sections' is not a valid view function or pattern name.
26.12.2023 01:26:57 [ERROR] "GET /news/2/subscription_category?selected_category=%D0%A0%D0%B5%D1%86%D0%B5%D0%BF%D1%82%D1%8B HTTP/1.1" 500 91599
C:\Users\user\projects\Skillfactory\Project News Portal\venv\Lib\site-packages\django\core\servers\basehttp.py
None
26.12.2023 01:28:43 [ERROR] Internal Server Error: /news/2/subscription_category
C:\Users\user\projects\Skillfactory\Project News Portal\venv\Lib\site-packages\django\utils\log.py
(<class 'django.urls.exceptions.NoReverseMatch'>, NoReverseMatch("Reverse for 'categories.html' not found. 'categories.html' is not a valid view function or pattern name."), <traceback object at 0x0000012E0F9C9E00>)
Traceback (most recent call last):
  File "C:\Users\user\projects\Skillfactory\Project News Portal\venv\Lib\site-packages\django\core\handlers\exception.py", line 55, in inner
    response = get_response(request)
               ^^^^^^^^^^^^^^^^^^^^^
  File "C:\Users\user\projects\Skillfactory\Project News Portal\venv\Lib\site-packages\django\core\handlers\base.py", line 197, in _get_response
    response = wrapped_callback(request, *callback_args, **callback_kwargs)
               ^^^^^^^^^^^^^^^^^^^^^^^^^^^^^^^^^^^^^^^^^^^^^^^^^^^^^^^^^^^^
  File "C:\Users\user\projects\Skillfactory\Project News Portal\venv\Lib\site-packages\django\contrib\auth\decorators.py", line 23, in _wrapper_view
    return view_func(request, *args, **kwargs)
           ^^^^^^^^^^^^^^^^^^^^^^^^^^^^^^^^^^^
  File "C:\Users\user\projects\Skillfactory\Project News Portal\News_Portal\news\views.py", line 140, in subscribe_category
    return render(request, 'subscription_category.html', {'redirect_to': reverse('categories.html')})
                                                                         ^^^^^^^^^^^^^^^^^^^^^^^^^^
  File "C:\Users\user\projects\Skillfactory\Project News Portal\venv\Lib\site-packages\django\urls\base.py", line 88, in reverse
    return resolver._reverse_with_prefix(view, prefix, *args, **kwargs)
           ^^^^^^^^^^^^^^^^^^^^^^^^^^^^^^^^^^^^^^^^^^^^^^^^^^^^^^^^^^^^
  File "C:\Users\user\projects\Skillfactory\Project News Portal\venv\Lib\site-packages\django\urls\resolvers.py", line 828, in _reverse_with_prefix
    raise NoReverseMatch(msg)
django.urls.exceptions.NoReverseMatch: Reverse for 'categories.html' not found. 'categories.html' is not a valid view function or pattern name.
26.12.2023 01:28:43 [ERROR] "GET /news/2/subscription_category?selected_category=%D0%A0%D0%B5%D1%86%D0%B5%D0%BF%D1%82%D1%8B HTTP/1.1" 500 91508
C:\Users\user\projects\Skillfactory\Project News Portal\venv\Lib\site-packages\django\core\servers\basehttp.py
None
26.12.2023 01:45:41 [ERROR] Internal Server Error: /news/2/subscription_category
C:\Users\user\projects\Skillfactory\Project News Portal\venv\Lib\site-packages\django\utils\log.py
(<class 'django.template.exceptions.TemplateDoesNotExist'>, TemplateDoesNotExist('/news/categories'), <traceback object at 0x000002554B4C4F00>)
Traceback (most recent call last):
  File "C:\Users\user\projects\Skillfactory\Project News Portal\venv\Lib\site-packages\django\core\handlers\exception.py", line 55, in inner
    response = get_response(request)
               ^^^^^^^^^^^^^^^^^^^^^
  File "C:\Users\user\projects\Skillfactory\Project News Portal\venv\Lib\site-packages\django\core\handlers\base.py", line 197, in _get_response
    response = wrapped_callback(request, *callback_args, **callback_kwargs)
               ^^^^^^^^^^^^^^^^^^^^^^^^^^^^^^^^^^^^^^^^^^^^^^^^^^^^^^^^^^^^
  File "C:\Users\user\projects\Skillfactory\Project News Portal\venv\Lib\site-packages\django\contrib\auth\decorators.py", line 23, in _wrapper_view
    return view_func(request, *args, **kwargs)
           ^^^^^^^^^^^^^^^^^^^^^^^^^^^^^^^^^^^
  File "C:\Users\user\projects\Skillfactory\Project News Portal\News_Portal\news\views.py", line 140, in subscribe_category
    return render(request, '/news/categories')
           ^^^^^^^^^^^^^^^^^^^^^^^^^^^^^^^^^^^
  File "C:\Users\user\projects\Skillfactory\Project News Portal\venv\Lib\site-packages\django\shortcuts.py", line 24, in render
    content = loader.render_to_string(template_name, context, request, using=using)
              ^^^^^^^^^^^^^^^^^^^^^^^^^^^^^^^^^^^^^^^^^^^^^^^^^^^^^^^^^^^^^^^^^^^^^
  File "C:\Users\user\projects\Skillfactory\Project News Portal\venv\Lib\site-packages\django\template\loader.py", line 61, in render_to_string
    template = get_template(template_name, using=using)
               ^^^^^^^^^^^^^^^^^^^^^^^^^^^^^^^^^^^^^^^^
  File "C:\Users\user\projects\Skillfactory\Project News Portal\venv\Lib\site-packages\django\template\loader.py", line 19, in get_template
    raise TemplateDoesNotExist(template_name, chain=chain)
django.template.exceptions.TemplateDoesNotExist: /news/categories
26.12.2023 01:45:41 [ERROR] "GET /news/2/subscription_category?selected_category=%D0%A0%D0%B5%D1%86%D0%B5%D0%BF%D1%82%D1%8B HTTP/1.1" 500 94743
C:\Users\user\projects\Skillfactory\Project News Portal\venv\Lib\site-packages\django\core\servers\basehttp.py
None
03.01.2024 17:11:55 [ERROR] Internal Server Error: /category/
C:\Users\user\projects\Skillfactory\Project News Portal\venv\Lib\site-packages\django\utils\log.py
(<class 'TypeError'>, TypeError('The `fields` option must be a list or tuple or "__all__". Got str.'), <traceback object at 0x000001B863822940>)
Traceback (most recent call last):
  File "C:\Users\user\projects\Skillfactory\Project News Portal\venv\Lib\site-packages\django\core\handlers\exception.py", line 55, in inner
    response = get_response(request)
               ^^^^^^^^^^^^^^^^^^^^^
  File "C:\Users\user\projects\Skillfactory\Project News Portal\venv\Lib\site-packages\django\core\handlers\base.py", line 197, in _get_response
    response = wrapped_callback(request, *callback_args, **callback_kwargs)
               ^^^^^^^^^^^^^^^^^^^^^^^^^^^^^^^^^^^^^^^^^^^^^^^^^^^^^^^^^^^^
  File "C:\Users\user\projects\Skillfactory\Project News Portal\venv\Lib\site-packages\django\views\decorators\csrf.py", line 56, in wrapper_view
    return view_func(*args, **kwargs)
           ^^^^^^^^^^^^^^^^^^^^^^^^^^
  File "C:\Users\user\projects\Skillfactory\Project News Portal\venv\Lib\site-packages\rest_framework\viewsets.py", line 125, in view
    return self.dispatch(request, *args, **kwargs)
           ^^^^^^^^^^^^^^^^^^^^^^^^^^^^^^^^^^^^^^^
  File "C:\Users\user\projects\Skillfactory\Project News Portal\venv\Lib\site-packages\rest_framework\views.py", line 509, in dispatch
    response = self.handle_exception(exc)
               ^^^^^^^^^^^^^^^^^^^^^^^^^^
  File "C:\Users\user\projects\Skillfactory\Project News Portal\venv\Lib\site-packages\rest_framework\views.py", line 469, in handle_exception
    self.raise_uncaught_exception(exc)
  File "C:\Users\user\projects\Skillfactory\Project News Portal\venv\Lib\site-packages\rest_framework\views.py", line 480, in raise_uncaught_exception
    raise exc
  File "C:\Users\user\projects\Skillfactory\Project News Portal\venv\Lib\site-packages\rest_framework\views.py", line 506, in dispatch
    response = handler(request, *args, **kwargs)
               ^^^^^^^^^^^^^^^^^^^^^^^^^^^^^^^^^
  File "C:\Users\user\projects\Skillfactory\Project News Portal\venv\Lib\site-packages\rest_framework\mixins.py", line 43, in list
    return self.get_paginated_response(serializer.data)
                                       ^^^^^^^^^^^^^^^
  File "C:\Users\user\projects\Skillfactory\Project News Portal\venv\Lib\site-packages\rest_framework\serializers.py", line 768, in data
    ret = super().data
          ^^^^^^^^^^^^
  File "C:\Users\user\projects\Skillfactory\Project News Portal\venv\Lib\site-packages\rest_framework\serializers.py", line 253, in data
    self._data = self.to_representation(self.instance)
                 ^^^^^^^^^^^^^^^^^^^^^^^^^^^^^^^^^^^^^
  File "C:\Users\user\projects\Skillfactory\Project News Portal\venv\Lib\site-packages\rest_framework\serializers.py", line 686, in to_representation
    return [
           ^
  File "C:\Users\user\projects\Skillfactory\Project News Portal\venv\Lib\site-packages\rest_framework\serializers.py", line 687, in <listcomp>
    self.child.to_representation(item) for item in iterable
    ^^^^^^^^^^^^^^^^^^^^^^^^^^^^^^^^^^
  File "C:\Users\user\projects\Skillfactory\Project News Portal\venv\Lib\site-packages\rest_framework\serializers.py", line 507, in to_representation
    for field in fields:
  File "C:\Users\user\projects\Skillfactory\Project News Portal\venv\Lib\site-packages\rest_framework\serializers.py", line 368, in _readable_fields
    for field in self.fields.values():
                 ^^^^^^^^^^^
  File "C:\Users\user\projects\Skillfactory\Project News Portal\venv\Lib\site-packages\django\utils\functional.py", line 57, in __get__
    res = instance.__dict__[self.name] = self.func(instance)
                                         ^^^^^^^^^^^^^^^^^^^
  File "C:\Users\user\projects\Skillfactory\Project News Portal\venv\Lib\site-packages\rest_framework\serializers.py", line 356, in fields
    for key, value in self.get_fields().items():
                      ^^^^^^^^^^^^^^^^^
  File "C:\Users\user\projects\Skillfactory\Project News Portal\venv\Lib\site-packages\rest_framework\serializers.py", line 1052, in get_fields
    field_names = self.get_field_names(declared_fields, info)
                  ^^^^^^^^^^^^^^^^^^^^^^^^^^^^^^^^^^^^^^^^^^^
  File "C:\Users\user\projects\Skillfactory\Project News Portal\venv\Lib\site-packages\rest_framework\serializers.py", line 1106, in get_field_names
    raise TypeError(
TypeError: The `fields` option must be a list or tuple or "__all__". Got str.
03.01.2024 17:11:55 [ERROR] "GET /category/?format=api HTTP/1.1" 500 151169
C:\Users\user\projects\Skillfactory\Project News Portal\venv\Lib\site-packages\django\core\servers\basehttp.py
None
03.01.2024 17:12:01 [ERROR] Internal Server Error: /category/
C:\Users\user\projects\Skillfactory\Project News Portal\venv\Lib\site-packages\django\utils\log.py
(<class 'TypeError'>, TypeError('The `fields` option must be a list or tuple or "__all__". Got str.'), <traceback object at 0x000001B863942F40>)
Traceback (most recent call last):
  File "C:\Users\user\projects\Skillfactory\Project News Portal\venv\Lib\site-packages\django\core\handlers\exception.py", line 55, in inner
    response = get_response(request)
               ^^^^^^^^^^^^^^^^^^^^^
  File "C:\Users\user\projects\Skillfactory\Project News Portal\venv\Lib\site-packages\django\core\handlers\base.py", line 197, in _get_response
    response = wrapped_callback(request, *callback_args, **callback_kwargs)
               ^^^^^^^^^^^^^^^^^^^^^^^^^^^^^^^^^^^^^^^^^^^^^^^^^^^^^^^^^^^^
  File "C:\Users\user\projects\Skillfactory\Project News Portal\venv\Lib\site-packages\django\views\decorators\csrf.py", line 56, in wrapper_view
    return view_func(*args, **kwargs)
           ^^^^^^^^^^^^^^^^^^^^^^^^^^
  File "C:\Users\user\projects\Skillfactory\Project News Portal\venv\Lib\site-packages\rest_framework\viewsets.py", line 125, in view
    return self.dispatch(request, *args, **kwargs)
           ^^^^^^^^^^^^^^^^^^^^^^^^^^^^^^^^^^^^^^^
  File "C:\Users\user\projects\Skillfactory\Project News Portal\venv\Lib\site-packages\rest_framework\views.py", line 509, in dispatch
    response = self.handle_exception(exc)
               ^^^^^^^^^^^^^^^^^^^^^^^^^^
  File "C:\Users\user\projects\Skillfactory\Project News Portal\venv\Lib\site-packages\rest_framework\views.py", line 469, in handle_exception
    self.raise_uncaught_exception(exc)
  File "C:\Users\user\projects\Skillfactory\Project News Portal\venv\Lib\site-packages\rest_framework\views.py", line 480, in raise_uncaught_exception
    raise exc
  File "C:\Users\user\projects\Skillfactory\Project News Portal\venv\Lib\site-packages\rest_framework\views.py", line 506, in dispatch
    response = handler(request, *args, **kwargs)
               ^^^^^^^^^^^^^^^^^^^^^^^^^^^^^^^^^
  File "C:\Users\user\projects\Skillfactory\Project News Portal\venv\Lib\site-packages\rest_framework\mixins.py", line 43, in list
    return self.get_paginated_response(serializer.data)
                                       ^^^^^^^^^^^^^^^
  File "C:\Users\user\projects\Skillfactory\Project News Portal\venv\Lib\site-packages\rest_framework\serializers.py", line 768, in data
    ret = super().data
          ^^^^^^^^^^^^
  File "C:\Users\user\projects\Skillfactory\Project News Portal\venv\Lib\site-packages\rest_framework\serializers.py", line 253, in data
    self._data = self.to_representation(self.instance)
                 ^^^^^^^^^^^^^^^^^^^^^^^^^^^^^^^^^^^^^
  File "C:\Users\user\projects\Skillfactory\Project News Portal\venv\Lib\site-packages\rest_framework\serializers.py", line 686, in to_representation
    return [
           ^
  File "C:\Users\user\projects\Skillfactory\Project News Portal\venv\Lib\site-packages\rest_framework\serializers.py", line 687, in <listcomp>
    self.child.to_representation(item) for item in iterable
    ^^^^^^^^^^^^^^^^^^^^^^^^^^^^^^^^^^
  File "C:\Users\user\projects\Skillfactory\Project News Portal\venv\Lib\site-packages\rest_framework\serializers.py", line 507, in to_representation
    for field in fields:
  File "C:\Users\user\projects\Skillfactory\Project News Portal\venv\Lib\site-packages\rest_framework\serializers.py", line 368, in _readable_fields
    for field in self.fields.values():
                 ^^^^^^^^^^^
  File "C:\Users\user\projects\Skillfactory\Project News Portal\venv\Lib\site-packages\django\utils\functional.py", line 57, in __get__
    res = instance.__dict__[self.name] = self.func(instance)
                                         ^^^^^^^^^^^^^^^^^^^
  File "C:\Users\user\projects\Skillfactory\Project News Portal\venv\Lib\site-packages\rest_framework\serializers.py", line 356, in fields
    for key, value in self.get_fields().items():
                      ^^^^^^^^^^^^^^^^^
  File "C:\Users\user\projects\Skillfactory\Project News Portal\venv\Lib\site-packages\rest_framework\serializers.py", line 1052, in get_fields
    field_names = self.get_field_names(declared_fields, info)
                  ^^^^^^^^^^^^^^^^^^^^^^^^^^^^^^^^^^^^^^^^^^^
  File "C:\Users\user\projects\Skillfactory\Project News Portal\venv\Lib\site-packages\rest_framework\serializers.py", line 1106, in get_field_names
    raise TypeError(
TypeError: The `fields` option must be a list or tuple or "__all__". Got str.
03.01.2024 17:12:02 [ERROR] "GET /category/ HTTP/1.1" 500 150748
C:\Users\user\projects\Skillfactory\Project News Portal\venv\Lib\site-packages\django\core\servers\basehttp.py
None
